2015-05-08 08:50:50,233 p=17140 u=Kal |   
2015-05-08 08:50:50,233 p=17140 u=Kal |  /usr/local/bin/ansible-playbook test_playbook/test.yml -i inv
2015-05-08 08:50:50,233 p=17140 u=Kal |   
2015-05-08 08:50:50,249 p=17140 u=Kal |  PLAY [all] ******************************************************************** 
2015-05-08 08:50:50,249 p=17140 u=Kal |  GATHERING FACTS *************************************************************** 
2015-05-08 08:50:50,436 p=17140 u=Kal |  ok: [localhost]
2015-05-08 08:50:50,436 p=17140 u=Kal |  TASK: [logs | Run a basic Command] ******************************************** 
2015-05-08 08:50:50,518 p=17140 u=Kal |  changed: [localhost]
2015-05-08 08:50:50,519 sample {"changed": true, "cmd": ["pwd"], "delta": "0:00:00.003078", "end": "2015-05-08 08:50:50.511985", "invocation": {"module_args": "pwd", "module_name": "command"}, "play": "test_playbook/test.yml", "rc": 0, "start": "2015-05-08 08:50:50.508907", "state": "ok", "stderr": "", "stdout": "/Users/Kal/git/sumo_logs/ansible/test_playbook", "warnings": []}
2015-05-08 08:50:50,519 p=17140 u=Kal |  TASK: [logs | Run a basic Command that would fail] **************************** 
2015-05-08 08:50:50,604 p=17140 u=Kal |  failed: [localhost] => {"changed": true, "cmd": ["pwd", "/something/wrong"], "delta": "0:00:00.003585", "end": "2015-05-08 08:50:50.597624", "rc": 1, "start": "2015-05-08 08:50:50.594039", "warnings": []}
2015-05-08 08:50:50,604 p=17140 u=Kal |  stderr: usage: pwd [-L | -P]
2015-05-08 08:50:50,604 sample {"changed": true, "cmd": ["pwd", "/something/wrong"], "delta": "0:00:00.003585", "end": "2015-05-08 08:50:50.597624", "invocation": {"module_args": "pwd /something/wrong", "module_name": "command"}, "play": "test_playbook/test.yml", "rc": 1, "start": "2015-05-08 08:50:50.594039", "state": "failed", "stderr": "usage: pwd [-L | -P]", "stdout": "", "warnings": []}
2015-05-08 08:50:50,604 p=17140 u=Kal |  FATAL: all hosts have already failed -- aborting
2015-05-08 08:50:50,605 p=17140 u=Kal |  PLAY RECAP ******************************************************************** 
2015-05-08 08:50:50,605 p=17140 u=Kal |             to retry, use: --limit @/Users/Kal/test.retry

2015-05-08 08:50:50,605 p=17140 u=Kal |  localhost                  : ok=2    changed=1    unreachable=0    failed=1   
2015-05-08 08:51:38,205 p=17187 u=Kal |   
2015-05-08 08:51:38,205 p=17187 u=Kal |  /usr/local/bin/ansible-playbook test_playbook/test.yml -i inv
2015-05-08 08:51:38,205 p=17187 u=Kal |   
2015-05-08 11:58:35,373 p=17781 u=Kal |   
2015-05-08 11:58:35,375 p=17781 u=Kal |  /usr/local/bin/ansible-playbook test_playbook/test.yml -i inv
2015-05-08 11:58:35,375 p=17781 u=Kal |   
2015-05-08 11:58:35,428 p=17781 u=Kal |  PLAY [all] ******************************************************************** 
2015-05-08 11:58:35,429 p=17781 u=Kal |  GATHERING FACTS *************************************************************** 
2015-05-08 11:58:35,694 p=17781 u=Kal |  ok: [localhost]
2015-05-08 11:58:35,695 p=17781 u=Kal |  TASK: [logs | Run a basic Command] ******************************************** 
2015-05-08 11:58:35,783 p=17781 u=Kal |  changed: [localhost]
2015-05-08 11:58:35,783 sample {"changed": true, "cmd": ["pwd"], "delta": "0:00:00.005027", "end": "2015-05-08 11:58:35.776089", "invocation": {"module_args": "pwd", "module_name": "command"}, "play": "test_playbook/test.yml", "rc": 0, "start": "2015-05-08 11:58:35.771062", "state": "ok", "stderr": "", "stdout": "/Users/Kal/git/sumo_logs/ansible/test_playbook", "warnings": []}
2015-05-08 11:58:35,784 p=17781 u=Kal |  TASK: [logs | Run a basic Command that would fail] **************************** 
2015-05-08 11:58:35,868 p=17781 u=Kal |  failed: [localhost] => {"changed": true, "cmd": ["pwd", "/something/wrong"], "delta": "0:00:00.003661", "end": "2015-05-08 11:58:35.860735", "rc": 1, "start": "2015-05-08 11:58:35.857074", "warnings": []}
2015-05-08 11:58:35,869 p=17781 u=Kal |  stderr: usage: pwd [-L | -P]
2015-05-08 11:58:35,869 sample {"changed": true, "cmd": ["pwd", "/something/wrong"], "delta": "0:00:00.003661", "end": "2015-05-08 11:58:35.860735", "invocation": {"module_args": "pwd /something/wrong", "module_name": "command"}, "play": "test_playbook/test.yml", "rc": 1, "start": "2015-05-08 11:58:35.857074", "state": "failed", "stderr": "usage: pwd [-L | -P]", "stdout": "", "warnings": []}
2015-05-08 11:58:35,869 p=17781 u=Kal |  FATAL: all hosts have already failed -- aborting
2015-05-08 11:58:35,869 p=17781 u=Kal |  PLAY RECAP ******************************************************************** 
2015-05-08 11:58:35,871 p=17781 u=Kal |             to retry, use: --limit @/Users/Kal/test.retry

2015-05-08 11:58:35,871 p=17781 u=Kal |  localhost                  : ok=2    changed=1    unreachable=0    failed=1   
2015-05-08 12:02:56,319 p=17852 u=Kal |   
2015-05-08 12:02:56,320 p=17852 u=Kal |  /usr/local/bin/ansible-playbook test_playbook/test.yml -i inv
2015-05-08 12:02:56,320 p=17852 u=Kal |   
2015-05-08 12:06:37,165 p=17876 u=Kal |   
2015-05-08 12:06:37,165 p=17876 u=Kal |  /usr/local/bin/ansible-playbook test_playbook/test.yml -i inv
2015-05-08 12:06:37,165 p=17876 u=Kal |   
2015-05-08 12:07:13,706 p=17882 u=Kal |   
2015-05-08 12:07:13,706 p=17882 u=Kal |  /usr/local/bin/ansible-playbook test_playbook/test.yml -i inv
2015-05-08 12:07:13,707 p=17882 u=Kal |   
2015-05-08 12:07:39,869 p=17886 u=Kal |   
2015-05-08 12:07:39,869 p=17886 u=Kal |  /usr/local/bin/ansible-playbook test_playbook/test.yml -i inv
2015-05-08 12:07:39,869 p=17886 u=Kal |   
2015-05-08 12:07:59,180 p=17890 u=Kal |   
2015-05-08 12:07:59,180 p=17890 u=Kal |  /usr/local/bin/ansible-playbook test_playbook/test.yml -i inv
2015-05-08 12:07:59,180 p=17890 u=Kal |   
2015-05-08 12:08:10,412 p=17893 u=Kal |   
2015-05-08 12:08:10,413 p=17893 u=Kal |  /usr/local/bin/ansible-playbook test_playbook/test.yml -i inv
2015-05-08 12:08:10,413 p=17893 u=Kal |   
2015-05-08 12:08:10,430 p=17893 u=Kal |  PLAY [all] ******************************************************************** 
2015-05-08 12:08:10,430 p=17893 u=Kal |  GATHERING FACTS *************************************************************** 
2015-05-08 12:08:11,240 p=17893 u=Kal |  ok: [localhost]
2015-05-08 12:08:11,243 p=17893 u=Kal |  fatal: [localhost] => Traceback (most recent call last):
  File "/Library/Python/2.7/site-packages/ansible/runner/__init__.py", line 590, in _executor
    exec_rc = self._executor_internal(host, new_stdin)
  File "/Library/Python/2.7/site-packages/ansible/runner/__init__.py", line 792, in _executor_internal
    return self._executor_internal_inner(host, self.module_name, self.module_args, inject, port, complex_args=complex_args)
  File "/Library/Python/2.7/site-packages/ansible/runner/__init__.py", line 1109, in _executor_internal_inner
    self.callbacks.on_ok(host, data)
  File "/Library/Python/2.7/site-packages/ansible/callbacks.py", line 539, in on_ok
    super(PlaybookRunnerCallbacks, self).on_ok(host, host_result)
  File "/Library/Python/2.7/site-packages/ansible/callbacks.py", line 345, in on_ok
    call_callback_module('runner_on_ok', host, res)
  File "/Library/Python/2.7/site-packages/ansible/callbacks.py", line 177, in call_callback_module
    method(*args, **kwargs)
  File "/Users/Kal/git/sumo_logs/ansible/plugins/callback_plugins/sumo_logs.py", line 43, in runner_on_ok
    json_log(res, self.play_name, self.task_name, 'ok')
AttributeError: 'CallbackModule' object has no attribute 'task_name'

2015-05-08 12:09:13,253 p=17920 u=Kal |   
2015-05-08 12:09:13,253 p=17920 u=Kal |  /usr/local/bin/ansible-playbook test_playbook/test.yml -i inv
2015-05-08 12:09:13,253 p=17920 u=Kal |   
2015-05-08 12:09:13,270 p=17920 u=Kal |  PLAY [all] ******************************************************************** 
2015-05-08 12:09:13,270 p=17920 u=Kal |  GATHERING FACTS *************************************************************** 
2015-05-08 12:09:13,477 p=17920 u=Kal |  ok: [localhost]
2015-05-08 12:09:13,478 p=17920 u=Kal |  fatal: [localhost] => Traceback (most recent call last):
  File "/Library/Python/2.7/site-packages/ansible/runner/__init__.py", line 590, in _executor
    exec_rc = self._executor_internal(host, new_stdin)
  File "/Library/Python/2.7/site-packages/ansible/runner/__init__.py", line 792, in _executor_internal
    return self._executor_internal_inner(host, self.module_name, self.module_args, inject, port, complex_args=complex_args)
  File "/Library/Python/2.7/site-packages/ansible/runner/__init__.py", line 1109, in _executor_internal_inner
    self.callbacks.on_ok(host, data)
  File "/Library/Python/2.7/site-packages/ansible/callbacks.py", line 539, in on_ok
    super(PlaybookRunnerCallbacks, self).on_ok(host, host_result)
  File "/Library/Python/2.7/site-packages/ansible/callbacks.py", line 345, in on_ok
    call_callback_module('runner_on_ok', host, res)
  File "/Library/Python/2.7/site-packages/ansible/callbacks.py", line 177, in call_callback_module
    method(*args, **kwargs)
  File "/Users/Kal/git/sumo_logs/ansible/plugins/callback_plugins/sumo_logs.py", line 43, in runner_on_ok
    json_log(res, self.play_name, self.task_name, 'ok')
AttributeError: 'CallbackModule' object has no attribute 'task_name'

2015-05-08 12:12:58,391 p=17955 u=Kal |   
2015-05-08 12:12:58,391 p=17955 u=Kal |  /usr/local/bin/ansible-playbook test_playbook/test.yml -i inv
2015-05-08 12:12:58,392 p=17955 u=Kal |   
2015-05-08 12:12:58,408 p=17955 u=Kal |  PLAY [all] ******************************************************************** 
2015-05-08 12:12:58,408 p=17955 u=Kal |  GATHERING FACTS *************************************************************** 
2015-05-08 12:12:59,205 p=17955 u=Kal |  ok: [localhost]
2015-05-08 12:12:59,206 p=17955 u=Kal |  fatal: [localhost] => Traceback (most recent call last):
  File "/Library/Python/2.7/site-packages/ansible/runner/__init__.py", line 590, in _executor
    exec_rc = self._executor_internal(host, new_stdin)
  File "/Library/Python/2.7/site-packages/ansible/runner/__init__.py", line 792, in _executor_internal
    return self._executor_internal_inner(host, self.module_name, self.module_args, inject, port, complex_args=complex_args)
  File "/Library/Python/2.7/site-packages/ansible/runner/__init__.py", line 1109, in _executor_internal_inner
    self.callbacks.on_ok(host, data)
  File "/Library/Python/2.7/site-packages/ansible/callbacks.py", line 539, in on_ok
    super(PlaybookRunnerCallbacks, self).on_ok(host, host_result)
  File "/Library/Python/2.7/site-packages/ansible/callbacks.py", line 345, in on_ok
    call_callback_module('runner_on_ok', host, res)
  File "/Library/Python/2.7/site-packages/ansible/callbacks.py", line 177, in call_callback_module
    method(*args, **kwargs)
  File "/Users/Kal/git/sumo_logs/ansible/plugins/callback_plugins/sumo_logs.py", line 42, in runner_on_ok
    json_log(res, self.play_name, self.task_name, 'ok')
AttributeError: 'CallbackModule' object has no attribute 'task_name'

2015-05-08 12:16:57,726 p=18004 u=Kal |   
2015-05-08 12:16:57,726 p=18004 u=Kal |  /usr/local/bin/ansible-playbook test_playbook/test.yml -i inv
2015-05-08 12:16:57,726 p=18004 u=Kal |   
2015-05-08 12:16:57,743 p=18004 u=Kal |  PLAY [all] ******************************************************************** 
2015-05-08 12:16:57,743 p=18004 u=Kal |  GATHERING FACTS *************************************************************** 
2015-05-08 12:16:58,548 p=18004 u=Kal |  ok: [localhost]
2015-05-08 12:16:58,549 p=18004 u=Kal |  fatal: [localhost] => Traceback (most recent call last):
  File "/Library/Python/2.7/site-packages/ansible/runner/__init__.py", line 590, in _executor
    exec_rc = self._executor_internal(host, new_stdin)
  File "/Library/Python/2.7/site-packages/ansible/runner/__init__.py", line 792, in _executor_internal
    return self._executor_internal_inner(host, self.module_name, self.module_args, inject, port, complex_args=complex_args)
  File "/Library/Python/2.7/site-packages/ansible/runner/__init__.py", line 1109, in _executor_internal_inner
    self.callbacks.on_ok(host, data)
  File "/Library/Python/2.7/site-packages/ansible/callbacks.py", line 539, in on_ok
    super(PlaybookRunnerCallbacks, self).on_ok(host, host_result)
  File "/Library/Python/2.7/site-packages/ansible/callbacks.py", line 345, in on_ok
    call_callback_module('runner_on_ok', host, res)
  File "/Library/Python/2.7/site-packages/ansible/callbacks.py", line 177, in call_callback_module
    method(*args, **kwargs)
  File "/Users/Kal/git/sumo_logs/ansible/plugins/callback_plugins/sumo_logs.py", line 43, in runner_on_ok
    json_log(res, self.play_name, self.task_name, 'ok')
AttributeError: 'CallbackModule' object has no attribute 'task_name'

2015-05-08 12:17:48,162 p=18031 u=Kal |   
2015-05-08 12:17:48,162 p=18031 u=Kal |  /usr/local/bin/ansible-playbook test_playbook/test.yml -i inv
2015-05-08 12:17:48,162 p=18031 u=Kal |   
2015-05-08 12:17:48,179 p=18031 u=Kal |  PLAY [all] ******************************************************************** 
2015-05-08 12:17:48,179 p=18031 u=Kal |  GATHERING FACTS *************************************************************** 
2015-05-08 12:17:48,382 p=18031 u=Kal |  ok: [localhost]
2015-05-08 12:17:48,383 p=18031 u=Kal |  fatal: [localhost] => Traceback (most recent call last):
  File "/Library/Python/2.7/site-packages/ansible/runner/__init__.py", line 590, in _executor
    exec_rc = self._executor_internal(host, new_stdin)
  File "/Library/Python/2.7/site-packages/ansible/runner/__init__.py", line 792, in _executor_internal
    return self._executor_internal_inner(host, self.module_name, self.module_args, inject, port, complex_args=complex_args)
  File "/Library/Python/2.7/site-packages/ansible/runner/__init__.py", line 1109, in _executor_internal_inner
    self.callbacks.on_ok(host, data)
  File "/Library/Python/2.7/site-packages/ansible/callbacks.py", line 539, in on_ok
    super(PlaybookRunnerCallbacks, self).on_ok(host, host_result)
  File "/Library/Python/2.7/site-packages/ansible/callbacks.py", line 345, in on_ok
    call_callback_module('runner_on_ok', host, res)
  File "/Library/Python/2.7/site-packages/ansible/callbacks.py", line 177, in call_callback_module
    method(*args, **kwargs)
  File "/Users/Kal/git/sumo_logs/ansible/plugins/callback_plugins/sumo_logs.py", line 43, in runner_on_ok
    json_log(res, self.play_name, self.task_name, 'ok')
AttributeError: 'CallbackModule' object has no attribute 'task_name'

2015-05-08 12:20:13,516 p=18070 u=Kal |   
2015-05-08 12:20:13,516 p=18070 u=Kal |  /usr/local/bin/ansible-playbook test_playbook/test.yml -i inv
2015-05-08 12:20:13,516 p=18070 u=Kal |   
2015-05-08 12:20:13,533 p=18070 u=Kal |  PLAY [all] ******************************************************************** 
2015-05-08 12:20:13,533 p=18070 u=Kal |  GATHERING FACTS *************************************************************** 
2015-05-08 12:20:13,741 p=18070 u=Kal |  ok: [localhost]
2015-05-08 12:20:13,742 p=18070 u=Kal |  fatal: [localhost] => Traceback (most recent call last):
  File "/Library/Python/2.7/site-packages/ansible/runner/__init__.py", line 590, in _executor
    exec_rc = self._executor_internal(host, new_stdin)
  File "/Library/Python/2.7/site-packages/ansible/runner/__init__.py", line 792, in _executor_internal
    return self._executor_internal_inner(host, self.module_name, self.module_args, inject, port, complex_args=complex_args)
  File "/Library/Python/2.7/site-packages/ansible/runner/__init__.py", line 1109, in _executor_internal_inner
    self.callbacks.on_ok(host, data)
  File "/Library/Python/2.7/site-packages/ansible/callbacks.py", line 539, in on_ok
    super(PlaybookRunnerCallbacks, self).on_ok(host, host_result)
  File "/Library/Python/2.7/site-packages/ansible/callbacks.py", line 345, in on_ok
    call_callback_module('runner_on_ok', host, res)
  File "/Library/Python/2.7/site-packages/ansible/callbacks.py", line 177, in call_callback_module
    method(*args, **kwargs)
  File "/Users/Kal/git/sumo_logs/ansible/plugins/callback_plugins/sumo_logs.py", line 45, in runner_on_ok
    json_log(res, self.play_name, self.task_name, 'ok')
AttributeError: 'CallbackModule' object has no attribute 'task_name'

2015-05-08 12:21:08,875 p=18102 u=Kal |   
2015-05-08 12:21:08,875 p=18102 u=Kal |  /usr/local/bin/ansible-playbook test_playbook/test.yml -i inv
2015-05-08 12:21:08,875 p=18102 u=Kal |   
2015-05-08 12:21:35,124 p=18109 u=Kal |   
2015-05-08 12:21:35,124 p=18109 u=Kal |  /usr/local/bin/ansible-playbook test_playbook/test.yml -i inv
2015-05-08 12:21:35,124 p=18109 u=Kal |   
2015-05-08 12:21:35,142 p=18109 u=Kal |  PLAY [all] ******************************************************************** 
2015-05-08 12:21:35,142 p=18109 u=Kal |  GATHERING FACTS *************************************************************** 
2015-05-08 12:21:35,346 p=18109 u=Kal |  ok: [localhost]
2015-05-08 12:21:35,347 p=18109 u=Kal |  fatal: [localhost] => Traceback (most recent call last):
  File "/Library/Python/2.7/site-packages/ansible/runner/__init__.py", line 590, in _executor
    exec_rc = self._executor_internal(host, new_stdin)
  File "/Library/Python/2.7/site-packages/ansible/runner/__init__.py", line 792, in _executor_internal
    return self._executor_internal_inner(host, self.module_name, self.module_args, inject, port, complex_args=complex_args)
  File "/Library/Python/2.7/site-packages/ansible/runner/__init__.py", line 1109, in _executor_internal_inner
    self.callbacks.on_ok(host, data)
  File "/Library/Python/2.7/site-packages/ansible/callbacks.py", line 539, in on_ok
    super(PlaybookRunnerCallbacks, self).on_ok(host, host_result)
  File "/Library/Python/2.7/site-packages/ansible/callbacks.py", line 345, in on_ok
    call_callback_module('runner_on_ok', host, res)
  File "/Library/Python/2.7/site-packages/ansible/callbacks.py", line 177, in call_callback_module
    method(*args, **kwargs)
  File "/Users/Kal/git/sumo_logs/ansible/plugins/callback_plugins/sumo_logs.py", line 46, in runner_on_ok
    json_log(res, self.play_name, self.task_name, 'ok')
AttributeError: 'CallbackModule' object has no attribute 'task_name'

2015-05-08 12:24:59,638 p=18152 u=Kal |   
2015-05-08 12:24:59,638 p=18152 u=Kal |  /usr/local/bin/ansible-playbook test_playbook/test.yml -i inv
2015-05-08 12:24:59,638 p=18152 u=Kal |   
2015-05-08 12:24:59,655 p=18152 u=Kal |  PLAY [all] ******************************************************************** 
2015-05-08 12:24:59,655 p=18152 u=Kal |  GATHERING FACTS *************************************************************** 
2015-05-08 12:24:59,965 p=18152 u=Kal |  ok: [localhost]
2015-05-08 12:24:59,966 p=18152 u=Kal |  fatal: [localhost] => Traceback (most recent call last):
  File "/Library/Python/2.7/site-packages/ansible/runner/__init__.py", line 590, in _executor
    exec_rc = self._executor_internal(host, new_stdin)
  File "/Library/Python/2.7/site-packages/ansible/runner/__init__.py", line 792, in _executor_internal
    return self._executor_internal_inner(host, self.module_name, self.module_args, inject, port, complex_args=complex_args)
  File "/Library/Python/2.7/site-packages/ansible/runner/__init__.py", line 1109, in _executor_internal_inner
    self.callbacks.on_ok(host, data)
  File "/Library/Python/2.7/site-packages/ansible/callbacks.py", line 539, in on_ok
    super(PlaybookRunnerCallbacks, self).on_ok(host, host_result)
  File "/Library/Python/2.7/site-packages/ansible/callbacks.py", line 345, in on_ok
    call_callback_module('runner_on_ok', host, res)
  File "/Library/Python/2.7/site-packages/ansible/callbacks.py", line 177, in call_callback_module
    method(*args, **kwargs)
  File "/Users/Kal/git/sumo_logs/ansible/plugins/callback_plugins/sumo_logs.py", line 46, in runner_on_ok
    json_log(res, self.play_name, self.task_name, 'ok')
AttributeError: 'CallbackModule' object has no attribute 'task_name'

2015-05-08 12:27:17,656 p=18188 u=Kal |   
2015-05-08 12:27:17,656 p=18188 u=Kal |  /usr/local/bin/ansible-playbook test_playbook/test.yml -i inv
2015-05-08 12:27:17,656 p=18188 u=Kal |   
2015-05-08 12:27:17,674 p=18188 u=Kal |  PLAY [all] ******************************************************************** 
2015-05-08 12:27:17,674 p=18188 u=Kal |  GATHERING FACTS *************************************************************** 
2015-05-08 12:27:17,886 p=18188 u=Kal |  ok: [localhost]
2015-05-08 12:27:17,887 p=18188 u=Kal |  fatal: [localhost] => Traceback (most recent call last):
  File "/Library/Python/2.7/site-packages/ansible/runner/__init__.py", line 590, in _executor
    exec_rc = self._executor_internal(host, new_stdin)
  File "/Library/Python/2.7/site-packages/ansible/runner/__init__.py", line 792, in _executor_internal
    return self._executor_internal_inner(host, self.module_name, self.module_args, inject, port, complex_args=complex_args)
  File "/Library/Python/2.7/site-packages/ansible/runner/__init__.py", line 1109, in _executor_internal_inner
    self.callbacks.on_ok(host, data)
  File "/Library/Python/2.7/site-packages/ansible/callbacks.py", line 539, in on_ok
    super(PlaybookRunnerCallbacks, self).on_ok(host, host_result)
  File "/Library/Python/2.7/site-packages/ansible/callbacks.py", line 345, in on_ok
    call_callback_module('runner_on_ok', host, res)
  File "/Library/Python/2.7/site-packages/ansible/callbacks.py", line 177, in call_callback_module
    method(*args, **kwargs)
  File "/Users/Kal/git/sumo_logs/ansible/plugins/callback_plugins/sumo_logs.py", line 44, in runner_on_ok
    json_log(res, self.play_name, self.task_name, 'ok')
AttributeError: 'CallbackModule' object has no attribute 'task_name'

2015-05-08 12:27:21,857 p=18214 u=Kal |   
2015-05-08 12:27:21,857 p=18214 u=Kal |  /usr/local/bin/ansible-playbook test_playbook/test.yml -i inv
2015-05-08 12:27:21,857 p=18214 u=Kal |   
2015-05-08 12:27:21,872 p=18214 u=Kal |  PLAY [all] ******************************************************************** 
2015-05-08 12:27:21,872 p=18214 u=Kal |  GATHERING FACTS *************************************************************** 
2015-05-08 12:27:22,073 p=18214 u=Kal |  ok: [localhost]
2015-05-08 12:27:22,074 p=18214 u=Kal |  fatal: [localhost] => Traceback (most recent call last):
  File "/Library/Python/2.7/site-packages/ansible/runner/__init__.py", line 590, in _executor
    exec_rc = self._executor_internal(host, new_stdin)
  File "/Library/Python/2.7/site-packages/ansible/runner/__init__.py", line 792, in _executor_internal
    return self._executor_internal_inner(host, self.module_name, self.module_args, inject, port, complex_args=complex_args)
  File "/Library/Python/2.7/site-packages/ansible/runner/__init__.py", line 1109, in _executor_internal_inner
    self.callbacks.on_ok(host, data)
  File "/Library/Python/2.7/site-packages/ansible/callbacks.py", line 539, in on_ok
    super(PlaybookRunnerCallbacks, self).on_ok(host, host_result)
  File "/Library/Python/2.7/site-packages/ansible/callbacks.py", line 345, in on_ok
    call_callback_module('runner_on_ok', host, res)
  File "/Library/Python/2.7/site-packages/ansible/callbacks.py", line 177, in call_callback_module
    method(*args, **kwargs)
  File "/Users/Kal/git/sumo_logs/ansible/plugins/callback_plugins/sumo_logs.py", line 44, in runner_on_ok
    json_log(res, self.play_name, self.task_name, 'ok')
AttributeError: 'CallbackModule' object has no attribute 'task_name'

2015-05-08 12:27:40,515 p=18241 u=Kal |   
2015-05-08 12:27:40,515 p=18241 u=Kal |  /usr/local/bin/ansible-playbook test_playbook/test.yml -i inv
2015-05-08 12:27:40,515 p=18241 u=Kal |   
2015-05-08 12:27:55,313 p=18244 u=Kal |   
2015-05-08 12:27:55,313 p=18244 u=Kal |  /usr/local/bin/ansible-playbook test_playbook/test.yml -i inv
2015-05-08 12:27:55,313 p=18244 u=Kal |   
2015-05-08 12:27:55,331 p=18244 u=Kal |  PLAY [all] ******************************************************************** 
2015-05-08 12:27:55,331 p=18244 u=Kal |  GATHERING FACTS *************************************************************** 
2015-05-08 12:27:55,535 p=18244 u=Kal |  ok: [localhost]
2015-05-08 12:27:55,536 p=18244 u=Kal |  fatal: [localhost] => Traceback (most recent call last):
  File "/Library/Python/2.7/site-packages/ansible/runner/__init__.py", line 590, in _executor
    exec_rc = self._executor_internal(host, new_stdin)
  File "/Library/Python/2.7/site-packages/ansible/runner/__init__.py", line 792, in _executor_internal
    return self._executor_internal_inner(host, self.module_name, self.module_args, inject, port, complex_args=complex_args)
  File "/Library/Python/2.7/site-packages/ansible/runner/__init__.py", line 1109, in _executor_internal_inner
    self.callbacks.on_ok(host, data)
  File "/Library/Python/2.7/site-packages/ansible/callbacks.py", line 539, in on_ok
    super(PlaybookRunnerCallbacks, self).on_ok(host, host_result)
  File "/Library/Python/2.7/site-packages/ansible/callbacks.py", line 345, in on_ok
    call_callback_module('runner_on_ok', host, res)
  File "/Library/Python/2.7/site-packages/ansible/callbacks.py", line 177, in call_callback_module
    method(*args, **kwargs)
  File "/Users/Kal/git/sumo_logs/ansible/plugins/callback_plugins/sumo_logs.py", line 44, in runner_on_ok
    json_log(res, self.play_name, self.task_name, 'ok')
AttributeError: 'CallbackModule' object has no attribute 'task_name'

2015-05-08 12:28:23,326 p=18274 u=Kal |   
2015-05-08 12:28:23,326 p=18274 u=Kal |  /usr/local/bin/ansible-playbook test_playbook/test.yml -i inv
2015-05-08 12:28:23,326 p=18274 u=Kal |   
2015-05-08 12:28:23,342 p=18274 u=Kal |  PLAY [all] ******************************************************************** 
2015-05-08 12:28:23,342 p=18274 u=Kal |  GATHERING FACTS *************************************************************** 
2015-05-08 12:28:23,546 p=18274 u=Kal |  ok: [localhost]
2015-05-08 12:28:23,547 p=18274 u=Kal |  fatal: [localhost] => Traceback (most recent call last):
  File "/Library/Python/2.7/site-packages/ansible/runner/__init__.py", line 590, in _executor
    exec_rc = self._executor_internal(host, new_stdin)
  File "/Library/Python/2.7/site-packages/ansible/runner/__init__.py", line 792, in _executor_internal
    return self._executor_internal_inner(host, self.module_name, self.module_args, inject, port, complex_args=complex_args)
  File "/Library/Python/2.7/site-packages/ansible/runner/__init__.py", line 1109, in _executor_internal_inner
    self.callbacks.on_ok(host, data)
  File "/Library/Python/2.7/site-packages/ansible/callbacks.py", line 539, in on_ok
    super(PlaybookRunnerCallbacks, self).on_ok(host, host_result)
  File "/Library/Python/2.7/site-packages/ansible/callbacks.py", line 345, in on_ok
    call_callback_module('runner_on_ok', host, res)
  File "/Library/Python/2.7/site-packages/ansible/callbacks.py", line 177, in call_callback_module
    method(*args, **kwargs)
  File "/Users/Kal/git/sumo_logs/ansible/plugins/callback_plugins/sumo_logs.py", line 44, in runner_on_ok
    json_log(res, self.play_name, self.task_name, 'ok')
AttributeError: 'CallbackModule' object has no attribute 'play_name'

2015-05-08 12:29:04,806 p=18310 u=Kal |   
2015-05-08 12:29:04,806 p=18310 u=Kal |  /usr/local/bin/ansible-playbook test_playbook/test.yml -i inv
2015-05-08 12:29:04,806 p=18310 u=Kal |   
2015-05-08 12:29:04,823 p=18310 u=Kal |  PLAY [all] ******************************************************************** 
2015-05-08 12:29:04,823 p=18310 u=Kal |  GATHERING FACTS *************************************************************** 
2015-05-08 12:29:05,028 p=18310 u=Kal |  ok: [localhost]
2015-05-08 12:29:05,029 p=18310 u=Kal |  TASK: [logs | Run a basic Command] ******************************************** 
2015-05-08 12:29:05,118 p=18310 u=Kal |  changed: [localhost]
2015-05-08 12:29:05,119 sample {"changed": true, "cmd": ["pwd"], "delta": "0:00:00.004919", "end": "2015-05-08 12:29:05.110807", "invocation": {"module_args": "pwd", "module_name": "command"}, "play": "test_playbook/test.yml", "rc": 0, "start": "2015-05-08 12:29:05.105888", "state": "ok", "stderr": "", "stdout": "/Users/Kal/git/sumo_logs/ansible/test_playbook", "task": null, "warnings": []}
2015-05-08 12:29:05,119 p=18310 u=Kal |  TASK: [logs | Run a basic Command that would fail] **************************** 
2015-05-08 12:29:05,207 p=18310 u=Kal |  failed: [localhost] => {"changed": true, "cmd": ["pwd", "/something/wrong"], "delta": "0:00:00.003816", "end": "2015-05-08 12:29:05.200130", "rc": 1, "start": "2015-05-08 12:29:05.196314", "warnings": []}
2015-05-08 12:29:05,208 p=18310 u=Kal |  stderr: usage: pwd [-L | -P]
2015-05-08 12:29:05,208 sample {"changed": true, "cmd": ["pwd", "/something/wrong"], "delta": "0:00:00.003816", "end": "2015-05-08 12:29:05.200130", "invocation": {"module_args": "pwd /something/wrong", "module_name": "command"}, "play": "test_playbook/test.yml", "rc": 1, "start": "2015-05-08 12:29:05.196314", "state": "failed", "stderr": "usage: pwd [-L | -P]", "stdout": "", "task": null, "warnings": []}
2015-05-08 12:29:05,208 p=18310 u=Kal |  FATAL: all hosts have already failed -- aborting
2015-05-08 12:29:05,208 p=18310 u=Kal |  PLAY RECAP ******************************************************************** 
2015-05-08 12:29:05,210 p=18310 u=Kal |             to retry, use: --limit @/Users/Kal/test.retry

2015-05-08 12:29:05,210 p=18310 u=Kal |  localhost                  : ok=2    changed=1    unreachable=0    failed=1   
2015-05-08 12:29:39,712 p=18355 u=Kal |   
2015-05-08 12:29:39,712 p=18355 u=Kal |  /usr/local/bin/ansible-playbook test_playbook/test.yml -i inv
2015-05-08 12:29:39,712 p=18355 u=Kal |   
2015-05-08 12:29:39,730 p=18355 u=Kal |  PLAY [all] ******************************************************************** 
2015-05-08 12:29:39,730 p=18355 u=Kal |  GATHERING FACTS *************************************************************** 
2015-05-08 12:29:39,949 p=18355 u=Kal |  ok: [localhost]
2015-05-08 12:29:39,949 p=18355 u=Kal |  TASK: [logs | Run a basic Command] ******************************************** 
2015-05-08 12:29:40,032 p=18355 u=Kal |  changed: [localhost]
2015-05-08 12:29:40,032 sample {"changed": true, "cmd": ["pwd"], "delta": "0:00:00.003497", "end": "2015-05-08 12:29:40.025098", "invocation": {"module_args": "pwd", "module_name": "command"}, "play": "test_playbook/test.yml", "rc": 0, "start": "2015-05-08 12:29:40.021601", "state": "ok", "stderr": "", "stdout": "/Users/Kal/git/sumo_logs/ansible/test_playbook", "task": null, "warnings": []}
2015-05-08 12:29:40,032 p=18355 u=Kal |  TASK: [logs | Run a basic Command that would fail] **************************** 
2015-05-08 12:29:40,117 p=18355 u=Kal |  failed: [localhost] => {"changed": true, "cmd": ["pwd", "/something/wrong"], "delta": "0:00:00.003757", "end": "2015-05-08 12:29:40.109103", "rc": 1, "start": "2015-05-08 12:29:40.105346", "warnings": []}
2015-05-08 12:29:40,117 p=18355 u=Kal |  stderr: usage: pwd [-L | -P]
2015-05-08 12:29:40,117 sample {"changed": true, "cmd": ["pwd", "/something/wrong"], "delta": "0:00:00.003757", "end": "2015-05-08 12:29:40.109103", "invocation": {"module_args": "pwd /something/wrong", "module_name": "command"}, "play": "test_playbook/test.yml", "rc": 1, "start": "2015-05-08 12:29:40.105346", "state": "failed", "stderr": "usage: pwd [-L | -P]", "stdout": "", "task": null, "warnings": []}
2015-05-08 12:29:40,117 p=18355 u=Kal |  FATAL: all hosts have already failed -- aborting
2015-05-08 12:29:40,118 p=18355 u=Kal |  PLAY RECAP ******************************************************************** 
2015-05-08 12:29:40,118 p=18355 u=Kal |             to retry, use: --limit @/Users/Kal/test.retry

2015-05-08 12:29:40,118 p=18355 u=Kal |  localhost                  : ok=2    changed=1    unreachable=0    failed=1   
2015-05-08 12:29:42,786 p=18395 u=Kal |   
2015-05-08 12:29:42,786 p=18395 u=Kal |  /usr/local/bin/ansible-playbook test_playbook/test.yml -i inv
2015-05-08 12:29:42,786 p=18395 u=Kal |   
2015-05-08 12:29:42,802 p=18395 u=Kal |  PLAY [all] ******************************************************************** 
2015-05-08 12:29:42,802 p=18395 u=Kal |  GATHERING FACTS *************************************************************** 
2015-05-08 12:29:43,007 p=18395 u=Kal |  ok: [localhost]
2015-05-08 12:29:43,008 p=18395 u=Kal |  TASK: [logs | Run a basic Command] ******************************************** 
2015-05-08 12:29:43,092 p=18395 u=Kal |  changed: [localhost]
2015-05-08 12:29:43,092 sample {"changed": true, "cmd": ["pwd"], "delta": "0:00:00.003821", "end": "2015-05-08 12:29:43.084843", "invocation": {"module_args": "pwd", "module_name": "command"}, "play": "test_playbook/test.yml", "rc": 0, "start": "2015-05-08 12:29:43.081022", "state": "ok", "stderr": "", "stdout": "/Users/Kal/git/sumo_logs/ansible/test_playbook", "task": null, "warnings": []}
2015-05-08 12:29:43,093 p=18395 u=Kal |  TASK: [logs | Run a basic Command that would fail] **************************** 
2015-05-08 12:29:43,181 p=18395 u=Kal |  failed: [localhost] => {"changed": true, "cmd": ["pwd", "/something/wrong"], "delta": "0:00:00.004066", "end": "2015-05-08 12:29:43.172731", "rc": 1, "start": "2015-05-08 12:29:43.168665", "warnings": []}
2015-05-08 12:29:43,181 p=18395 u=Kal |  stderr: usage: pwd [-L | -P]
2015-05-08 12:29:43,181 sample {"changed": true, "cmd": ["pwd", "/something/wrong"], "delta": "0:00:00.004066", "end": "2015-05-08 12:29:43.172731", "invocation": {"module_args": "pwd /something/wrong", "module_name": "command"}, "play": "test_playbook/test.yml", "rc": 1, "start": "2015-05-08 12:29:43.168665", "state": "failed", "stderr": "usage: pwd [-L | -P]", "stdout": "", "task": null, "warnings": []}
2015-05-08 12:29:43,181 p=18395 u=Kal |  FATAL: all hosts have already failed -- aborting
2015-05-08 12:29:43,181 p=18395 u=Kal |  PLAY RECAP ******************************************************************** 
2015-05-08 12:29:43,182 p=18395 u=Kal |             to retry, use: --limit @/Users/Kal/test.retry

2015-05-08 12:29:43,182 p=18395 u=Kal |  localhost                  : ok=2    changed=1    unreachable=0    failed=1   
2015-05-08 12:29:57,664 p=18441 u=Kal |   
2015-05-08 12:29:57,664 p=18441 u=Kal |  /usr/local/bin/ansible-playbook test_playbook/test.yml -i inv
2015-05-08 12:29:57,664 p=18441 u=Kal |   
2015-05-08 12:29:57,681 p=18441 u=Kal |  PLAY [all] ******************************************************************** 
2015-05-08 12:29:57,681 p=18441 u=Kal |  GATHERING FACTS *************************************************************** 
2015-05-08 12:29:57,878 p=18441 u=Kal |  ok: [localhost]
2015-05-08 12:29:57,878 p=18441 u=Kal |  TASK: [logs | Run a basic Command] ******************************************** 
2015-05-08 12:29:57,960 p=18441 u=Kal |  changed: [localhost]
2015-05-08 12:29:57,961 sample {"changed": true, "cmd": ["pwd"], "delta": "0:00:00.003296", "end": "2015-05-08 12:29:57.953474", "invocation": {"module_args": "pwd", "module_name": "command"}, "play": "test_playbook/test.yml", "rc": 0, "start": "2015-05-08 12:29:57.950178", "state": "ok", "stderr": "", "stdout": "/Users/Kal/git/sumo_logs/ansible/test_playbook", "task": null, "warnings": []}
2015-05-08 12:29:57,961 p=18441 u=Kal |  TASK: [logs | Run a basic Command that would fail] **************************** 
2015-05-08 12:29:58,047 p=18441 u=Kal |  failed: [localhost] => {"changed": true, "cmd": ["pwd", "/something/wrong"], "delta": "0:00:00.003978", "end": "2015-05-08 12:29:58.039568", "rc": 1, "start": "2015-05-08 12:29:58.035590", "warnings": []}
2015-05-08 12:29:58,047 p=18441 u=Kal |  stderr: usage: pwd [-L | -P]
2015-05-08 12:29:58,047 sample {"changed": true, "cmd": ["pwd", "/something/wrong"], "delta": "0:00:00.003978", "end": "2015-05-08 12:29:58.039568", "invocation": {"module_args": "pwd /something/wrong", "module_name": "command"}, "play": "test_playbook/test.yml", "rc": 1, "start": "2015-05-08 12:29:58.035590", "state": "failed", "stderr": "usage: pwd [-L | -P]", "stdout": "", "task": null, "warnings": []}
2015-05-08 12:29:58,047 p=18441 u=Kal |  FATAL: all hosts have already failed -- aborting
2015-05-08 12:29:58,047 p=18441 u=Kal |  PLAY RECAP ******************************************************************** 
2015-05-08 12:29:58,048 p=18441 u=Kal |             to retry, use: --limit @/Users/Kal/test.retry

2015-05-08 12:29:58,048 p=18441 u=Kal |  localhost                  : ok=2    changed=1    unreachable=0    failed=1   
2015-05-08 12:30:56,959 p=18489 u=Kal |   
2015-05-08 12:30:56,959 p=18489 u=Kal |  /usr/local/bin/ansible-playbook test_playbook/test.yml -i inv
2015-05-08 12:30:56,959 p=18489 u=Kal |   
2015-05-08 12:30:56,976 p=18489 u=Kal |  PLAY [all] ******************************************************************** 
2015-05-08 12:30:56,977 p=18489 u=Kal |  GATHERING FACTS *************************************************************** 
2015-05-08 12:30:57,178 p=18489 u=Kal |  ok: [localhost]
2015-05-08 12:30:57,179 p=18489 u=Kal |  TASK: [logs | Run a basic Command] ******************************************** 
2015-05-08 12:30:57,263 p=18489 u=Kal |  changed: [localhost]
2015-05-08 12:30:57,263 sample {"changed": true, "cmd": ["pwd"], "delta": "0:00:00.003579", "end": "2015-05-08 12:30:57.256005", "invocation": {"module_args": "pwd", "module_name": "command"}, "play": "test_playbook/test.yml", "rc": 0, "start": "2015-05-08 12:30:57.252426", "state": "ok", "stderr": "", "stdout": "/Users/Kal/git/sumo_logs/ansible/test_playbook", "task": "Run a basic Command", "warnings": []}
2015-05-08 12:30:57,263 p=18489 u=Kal |  TASK: [logs | Run a basic Command that would fail] **************************** 
2015-05-08 12:30:57,348 p=18489 u=Kal |  failed: [localhost] => {"changed": true, "cmd": ["pwd", "/something/wrong"], "delta": "0:00:00.003695", "end": "2015-05-08 12:30:57.341738", "rc": 1, "start": "2015-05-08 12:30:57.338043", "warnings": []}
2015-05-08 12:30:57,349 p=18489 u=Kal |  stderr: usage: pwd [-L | -P]
2015-05-08 12:30:57,349 sample {"changed": true, "cmd": ["pwd", "/something/wrong"], "delta": "0:00:00.003695", "end": "2015-05-08 12:30:57.341738", "invocation": {"module_args": "pwd /something/wrong", "module_name": "command"}, "play": "test_playbook/test.yml", "rc": 1, "start": "2015-05-08 12:30:57.338043", "state": "failed", "stderr": "usage: pwd [-L | -P]", "stdout": "", "task": "Run a basic Command that would fail", "warnings": []}
2015-05-08 12:30:57,349 p=18489 u=Kal |  FATAL: all hosts have already failed -- aborting
2015-05-08 12:30:57,349 p=18489 u=Kal |  PLAY RECAP ******************************************************************** 
2015-05-08 12:30:57,350 p=18489 u=Kal |             to retry, use: --limit @/Users/Kal/test.retry

2015-05-08 12:30:57,350 p=18489 u=Kal |  localhost                  : ok=2    changed=1    unreachable=0    failed=1   
